Workbook

Sheet Dashboard
A1: CHIRAG FLOWSCAPE — FLUID CONTACT DETECTOR
A2: Purpose: screen candidate GOC/OWC/GWC positions from formation-level fluid observations, TVD and thickness, while propagating a transparent contact-uncertainty envelope.
A5: Input records | B5: =COUNTA(Master_Data!A2:A1001)
A6: Direct contact candidates | B6: =COUNTIF(Contact_Detector!F2:F1000,"GOC")+COUNTIF(Contact_Detector!F2:F1000,"OWC")+COUNTIF(Contact_Detector!F2:F1000,"GWC")
A7: Transition intervals | B7: =COUNTIF(Contact_Detector!F2:F1000,"*TRANSITION*")
A8: Sw conflicts | B8: =COUNTIF(Contact_Detector!N2:N1000,"Conflicts")
A11: How to use
A12: 1. Enter/replace the master well data in Master_Data. Keep records for each well ordered from shallow to deep.
A13: 2. Enter TVD_SCS and Gross TST. If you have shifted thickness (TST-S), put it in TST_S (optional); the detector will use it preferentially.
A14: 3. Enter the fluid description in Fluids. The tool classifies it automatically. Use Fluid_Override only when the automatic class is not suitable.
A15: 4. Review Contact_Detector. Direct adjacent fluid transitions generate candidate GOC/OWC/GWC positions; mixed fluid intervals remain transition intervals.
A16: 5. Review uncertainty bounds and Sw_Check. A Sw conflict is a diagnostic flag, not proof that the contact is wrong.
A17: 6. Use Contact_Summary for per-well candidate statistics. These are screening outputs, not calibrated field contacts.
A18: 7. For the PhD workflow, later add pressure/rate/4D evidence and update the static prior with dynamic evidence/Bayesian analysis.
A21: Important scientific note
A22: This workbook is a transparent screening tool. It does not establish a measured field contact, a common OWC/GOC, or reservoir connectivity by itself. Your supplied research explicitly treats contact shifts as uncertainty and static connectivity as a prior that should be tested/updated with independent dynamic evidence.

Sheet Master_Data
A1: Well | B1: Formation | C1: TVD_SCS | D1: MD | E1: PHIT | F1: Av_PERM | G1: Sw | H1: Gross TST | I1: NTG | J1: Net_ROCK | K1: Net_RES | L1: Net_PAY | M1: Fluids | N1: Comment | O1: TST_S (optional) | P1: Fluid_Override (optional) | Q1: Fluid_Class | R1: Top_TVD | S1: Base_TVD | T1: Contact_Unc_m | U1: Data_Quality | V1: Detector_Note
A2: X1 | B2: Surakhany | Q2: =IF(P2<>"",P2,IF(M2="","UNKNOWN",IF(AND(ISNUMBER(SEARCH("gas",LOWER(M2))),ISNUMBER(SEARCH("water",LOWER(M2)))),"GAS_WATER",IF(AND(ISNUMBER(SEARCH("oil",LOWER(M2))),ISNUMBER(SEARCH("water",LOWER(M2)))),"OIL_WATER",IF(ISNUMBER(SEARCH("gas",LOWER(M2))),"GAS",IF(ISNUMBER(SEARCH("water",LOWER(M2))),"WATER",IF(ISNUMBER(SEARCH("oil",LOWER(M2))),"OIL","UNKNOWN"))))))) | R2: =IF(C2="","",C2) | S2: =IF(R2="","",R2+IF(O2<>"",O2,IF(H2="",0,H2))) | T2: =IF(R2="","",MAX(Settings!$B$3,Settings!$B$4*IF(O2<>"",O2,IF(H2="",0,H2)))) | U2: =IF(AND(C2<>"",M2<>"",OR(H2<>"",O2<>"")),"COMPLETE",IF(OR(C2<>"",M2<>""),"PARTIAL","MISSING")) | V2: =IF(Q2="UNKNOWN","Check fluid description",IF(AND(R2<>"",S2<>""),"Ready for contact screening","Needs TVD + thickness"))
A3: X1 | B3: Sabunchi | Q3: =IF(P3<>"",P3,IF(M3="","UNKNOWN",IF(AND(ISNUMBER(SEARCH("gas",LOWER(M3))),ISNUMBER(SEARCH("water",LOWER(M3)))),"GAS_WATER",IF(AND(ISNUMBER(SEARCH("oil",LOWER(M3))),ISNUMBER(SEARCH("water",LOWER(M3)))),"OIL_WATER",IF(ISNUMBER(SEARCH("gas",LOWER(M3))),"GAS",IF(ISNUMBER(SEARCH("water",LOWER(M3))),"WATER",IF(ISNUMBER(SEARCH("oil",LOWER(M3))),"OIL","UNKNOWN"))))))) | R3: =IF(C3="","",C3) | S3: =IF(R3="","",R3+IF(O3<>"",O3,IF(H3="",0,H3))) | T3: =IF(R3="","",MAX(Settings!$B$3,Settings!$B$4*IF(O3<>"",O3,IF(H3="",0,H3)))) | U3: =IF(AND(C3<>"",M3<>"",OR(H3<>"",O3<>"")),"COMPLETE",IF(OR(C3<>"",M3<>""),"PARTIAL","MISSING")) | V3: =IF(Q3="UNKNOWN","Check fluid description",IF(AND(R3<>"",S3<>""),"Ready for contact screening","Needs TVD + thickness"))
A4: X1 | B4: Sabunchi GM | Q4: =IF(P4<>"",P4,IF(M4="","UNKNOWN",IF(AND(ISNUMBER(SEARCH("gas",LOWER(M4))),ISNUMBER(SEARCH("water",LOWER(M4)))),"GAS_WATER",IF(AND(ISNUMBER(SEARCH("oil",LOWER(M4))),ISNUMBER(SEARCH("water",LOWER(M4)))),"OIL_WATER",IF(ISNUMBER(SEARCH("gas",LOWER(M4))),"GAS",IF(ISNUMBER(SEARCH("water",LOWER(M4))),"WATER",IF(ISNUMBER(SEARCH("oil",LOWER(M4))),"OIL","UNKNOWN"))))))) | R4: =IF(C4="","",C4) | S4: =IF(R4="","",R4+IF(O4<>"",O4,IF(H4="",0,H4))) | T4: =IF(R4="","",MAX(Settings!$B$3,Settings!$B$4*IF(O4<>"",O4,IF(H4="",0,H4)))) | U4: =IF(AND(C4<>"",M4<>"",OR(H4<>"",O4<>"")),"COMPLETE",IF(OR(C4<>"",M4<>""),"PARTIAL","MISSING")) | V4: =IF(Q4="UNKNOWN","Check fluid description",IF(AND(R4<>"",S4<>""),"Ready for contact screening","Needs TVD + thickness"))
A5: X1 | B5: Balakhany | Q5: =IF(P5<>"",P5,IF(M5="","UNKNOWN",IF(AND(ISNUMBER(SEARCH("gas",LOWER(M5))),ISNUMBER(SEARCH("water",LOWER(M5)))),"GAS_WATER",IF(AND(ISNUMBER(SEARCH("oil",LOWER(M5))),ISNUMBER(SEARCH("water",LOWER(M5)))),"OIL_WATER",IF(ISNUMBER(SEARCH("gas",LOWER(M5))),"GAS",IF(ISNUMBER(SEARCH("water",LOWER(M5))),"WATER",IF(ISNUMBER(SEARCH("oil",LOWER(M5))),"OIL","UNKNOWN"))))))) | R5: =IF(C5="","",C5) | S5: =IF(R5="","",R5+IF(O5<>"",O5,IF(H5="",0,H5))) | T5: =IF(R5="","",MAX(Settings!$B$3,Settings!$B$4*IF(O5<>"",O5,IF(H5="",0,H5)))) | U5: =IF(AND(C5<>"",M5<>"",OR(H5<>"",O5<>"")),"COMPLETE",IF(OR(C5<>"",M5<>""),"PARTIAL","MISSING")) | V5: =IF(Q5="UNKNOWN","Check fluid description",IF(AND(R5<>"",S5<>""),"Ready for contact screening","Needs TVD + thickness"))
A6: X1 | B6: Balakhany V | Q6: =IF(P6<>"",P6,IF(M6="","UNKNOWN",IF(AND(ISNUMBER(SEARCH("gas",LOWER(M6))),ISNUMBER(SEARCH("water",LOWER(M6)))),"GAS_WATER",IF(AND(ISNUMBER(SEARCH("oil",LOWER(M6))),ISNUMBER(SEARCH("water",LOWER(M6)))),"OIL_WATER",IF(ISNUMBER(SEARCH("gas",LOWER(M6))),"GAS",IF(ISNUMBER(SEARCH("water",LOWER(M6))),"WATER",IF(ISNUMBER(SEARCH("oil",LOWER(M6))),"OIL","UNKNOWN"))))))) | R6: =IF(C6="","",C6) | S6: =IF(R6="","",R6+IF(O6<>"",O6,IF(H6="",0,H6))) | T6: =IF(R6="","",MAX(Settings!$B$3,Settings!$B$4*IF(O6<>"",O6,IF(H6="",0,H6)))) | U6: =IF(AND(C6<>"",M6<>"",OR(H6<>"",O6<>"")),"COMPLETE",IF(OR(C6<>"",M6<>""),"PARTIAL","MISSING")) | V6: =IF(Q6="UNKNOWN","Check fluid description",IF(AND(R6<>"",S6<>""),"Ready for contact screening","Needs TVD + thickness"))
A7: X1 | B7: Balakhany VI | Q7: =IF(P7<>"",P7,IF(M7="","UNKNOWN",IF(AND(ISNUMBER(SEARCH("gas",LOWER(M7))),ISNUMBER(SEARCH("water",LOWER(M7)))),"GAS_WATER",IF(AND(ISNUMBER(SEARCH("oil",LOWER(M7))),ISNUMBER(SEARCH("water",LOWER(M7)))),"OIL_WATER",IF(ISNUMBER(SEARCH("gas",LOWER(M7))),"GAS",IF(ISNUMBER(SEARCH("water",LOWER(M7))),"WATER",IF(ISNUMBER(SEARCH("oil",LOWER(M7))),"OIL","UNKNOWN"))))))) | R7: =IF(C7="","",C7) | S7: =IF(R7="","",R7+IF(O7<>"",O7,IF(H7="",0,H7))) | T7: =IF(R7="","",MAX(Settings!$B$3,Settings!$B$4*IF(O7<>"",O7,IF(H7="",0,H7)))) | U7: =IF(AND(C7<>"",M7<>"",OR(H7<>"",O7<>"")),"COMPLETE",IF(OR(C7<>"",M7<>""),"PARTIAL","MISSING")) | V7: =IF(Q7="UNKNOWN","Check fluid description",IF(AND(R7<>"",S7<>""),"Ready for contact screening","Needs TVD + thickness"))
A8: X1 | B8: Balakhany VI Sand | Q8: =IF(P8<>"",P8,IF(M8="","UNKNOWN",IF(AND(ISNUMBER(SEARCH("gas",LOWER(M8))),ISNUMBER(SEARCH("water",LOWER(M8)))),"GAS_WATER",IF(AND(ISNUMBER(SEARCH("oil",LOWER(M8))),ISNUMBER(SEARCH("water",LOWER(M8)))),"OIL_WATER",IF(ISNUMBER(SEARCH("gas",LOWER(M8))),"GAS",IF(ISNUMBER(SEARCH("water",LOWER(M8))),"WATER",IF(ISNUMBER(SEARCH("oil",LOWER(M8))),"OIL","UNKNOWN"))))))) | R8: =IF(C8="","",C8) | S8: =IF(R8="","",R8+IF(O8<>"",O8,IF(H8="",0,H8))) | T8: =IF(R8="","",MAX(Settings!$B$3,Settings!$B$4*IF(O8<>"",O8,IF(H8="",0,H8)))) | U8: =IF(AND(C8<>"",M8<>"",OR(H8<>"",O8<>"")),"COMPLETE",IF(OR(C8<>"",M8<>""),"PARTIAL","MISSING")) | V8: =IF(Q8="UNKNOWN","Check fluid description",IF(AND(R8<>"",S8<>""),"Ready for contact screening","Needs TVD + thickness"))
A9: X1 | B9: Balakhany VII | Q9: =IF(P9<>"",P9,IF(M9="","UNKNOWN",IF(AND(ISNUMBER(SEARCH("gas",LOWER(M9))),ISNUMBER(SEARCH("water",LOWER(M9)))),"GAS_WATER",IF(AND(ISNUMBER(SEARCH("oil",LOWER(M9))),ISNUMBER(SEARCH("water",LOWER(M9)))),"OIL_WATER",IF(ISNUMBER(SEARCH("gas",LOWER(M9))),"GAS",IF(ISNUMBER(SEARCH("water",LOWER(M9))),"WATER",IF(ISNUMBER(SEARCH("oil",LOWER(M9))),"OIL","UNKNOWN"))))))) | R9: =IF(C9="","",C9) | S9: =IF(R9="","",R9+IF(O9<>"",O9,IF(H9="",0,H9))) | T9: =IF(R9="","",MAX(Settings!$B$3,Settings!$B$4*IF(O9<>"",O9,IF(H9="",0,H9)))) | U9: =IF(AND(C9<>"",M9<>"",OR(H9<>"",O9<>"")),"COMPLETE",IF(OR(C9<>"",M9<>""),"PARTIAL","MISSING")) | V9: =IF(Q9="UNKNOWN","Check fluid description",IF(AND(R9<>"",S9<>""),"Ready for contact screening","Needs TVD + thickness"))
A10: X1 | B10: Balakhany VII Sand | Q10: =IF(P10<>"",P10,IF(M10="","UNKNOWN",IF(AND(ISNUMBER(SEARCH("gas",LOWER(M10))),ISNUMBER(SEARCH("water",LOWER(M10)))),"GAS_WATER",IF(AND(ISNUMBER(SEARCH("oil",LOWER(M10))),ISNUMBER(SEARCH("water",LOWER(M10)))),"OIL_WATER",IF(ISNUMBER(SEARCH("gas",LOWER(M10))),"GAS",IF(ISNUMBER(SEARCH("water",LOWER(M10))),"WATER",IF(ISNUMBER(SEARCH("oil",LOWER(M10))),"OIL","UNKNOWN"))))))) | R10: =IF(C10="","",C10) | S10: =IF(R10="","",R10+IF(O10<>"",O10,IF(H10="",0,H10))) | T10: =IF(R10="","",MAX(Settings!$B$3,Settings!$B$4*IF(O10<>"",O10,IF(H10="",0,H10)))) | U10: =IF(AND(C10<>"",M10<>"",OR(H10<>"",O10<>"")),"COMPLETE",IF(OR(C10<>"",M10<>""),"PARTIAL","MISSING")) | V10: =IF(Q10="UNKNOWN","Check fluid description",IF(AND(R10<>"",S10<>""),"Ready for contact screening","Needs TVD + thickness"))
A11: X1 | B11: Balakhany VIII | Q11: =IF(P11<>"",P11,IF(M11="","UNKNOWN",IF(AND(ISNUMBER(SEARCH("gas",LOWER(M11))),ISNUMBER(SEARCH("water",LOWER(M11)))),"GAS_WATER",IF(AND(ISNUMBER(SEARCH("oil",LOWER(M11))),ISNUMBER(SEARCH("water",LOWER(M11)))),"OIL_WATER",IF(ISNUMBER(SEARCH("gas",LOWER(M11))),"GAS",IF(ISNUMBER(SEARCH("water",LOWER(M11))),"WATER",IF(ISNUMBER(SEARCH("oil",LOWER(M11))),"OIL","UNKNOWN"))))))) | R11: =IF(C11="","",C11) | S11: =IF(R11="","",R11+IF(O11<>"",O11,IF(H11="",0,H11))) | T11: =IF(R11="","",MAX(Settings!$B$3,Settings!$B$4*IF(O11<>"",O11,IF(H11="",0,H11)))) | U11: =IF(AND(C11<>"",M11<>"",OR(H11<>"",O11<>"")),"COMPLETE",IF(OR(C11<>"",M11<>""),"PARTIAL","MISSING")) | V11: =IF(Q11="UNKNOWN","Check fluid description",IF(AND(R11<>"",S11<>""),"Ready for contact screening","Needs TVD + thickness"))
A12: X1 | B12: Balakhany VIII Sand | Q12: =IF(P12<>"",P12,IF(M12="","UNKNOWN",IF(AND(ISNUMBER(SEARCH("gas",LOWER(M12))),ISNUMBER(SEARCH("water",LOWER(M12)))),"GAS_WATER",IF(AND(ISNUMBER(SEARCH("oil",LOWER(M12))),ISNUMBER(SEARCH("water",LOWER(M12)))),"OIL_WATER",IF(ISNUMBER(SEARCH("gas",LOWER(M12))),"GAS",IF(ISNUMBER(SEARCH("water",LOWER(M12))),"WATER",IF(ISNUMBER(SEARCH("oil",LOWER(M12))),"OIL","UNKNOWN"))))))) | R12: =IF(C12="","",C12) | S12: =IF(R12="","",R12+IF(O12<>"",O12,IF(H12="",0,H12))) | T12: =IF(R12="","",MAX(Settings!$B$3,Settings!$B$4*IF(O12<>"",O12,IF(H12="",0,H12)))) | U12: =IF(AND(C12<>"",M12<>"",OR(H12<>"",O12<>"")),"COMPLETE",IF(OR(C12<>"",M12<>""),"PARTIAL","MISSING")) | V12: =IF(Q12="UNKNOWN","Check fluid description",IF(AND(R12<>"",S12<>""),"Ready for contact screening","Needs TVD + thickness"))
A13: X1 | B13: Balakhany VIII 10 | Q13: =IF(P13<>"",P13,IF(M13="","UNKNOWN",IF(AND(ISNUMBER(SEARCH("gas",LOWER(M13))),ISNUMBER(SEARCH("water",LOWER(M13)))),"GAS_WATER",IF(AND(ISNUMBER(SEARCH("oil",LOWER(M13))),ISNUMBER(SEARCH("water",LOWER(M13)))),"OIL_WATER",IF(ISNUMBER(SEARCH("gas",LOWER(M13))),"GAS",IF(ISNUMBER(SEARCH("water",LOWER(M13))),"WATER",IF(ISNUMBER(SEARCH("oil",LOWER(M13))),"OIL","UNKNOWN"))))))) | R13: =IF(C13="","",C13) | S13: =IF(R13="","",R13+IF(O13<>"",O13,IF(H13="",0,H13))) | T13: =IF(R13="","",MAX(Settings!$B$3,Settings!$B$4*IF(O13<>"",O13,IF(H13="",0,H13)))) | U13: =IF(AND(C13<>"",M13<>"",OR(H13<>"",O13<>"")),"COMPLETE",IF(OR(C13<>"",M13<>""),"PARTIAL","MISSING")) | V13: =IF(Q13="UNKNOWN","Check fluid description",IF(AND(R13<>"",S13<>""),"Ready for contact screening","Needs TVD + thickness"))
... A29: X1 | B29: NKG | Q29: =IF(P29<>"",P29,IF(M29="","UNKNOWN",IF(AND(ISNUMBER(SEARCH("gas",LOWER(M29))),ISNUMBER(SEARCH("water",LOWER(M29)))),"GAS_WATER",IF(AND(ISNUMBER(SEARCH("oil",LOWER(M29))),ISNUMBER(SEARCH("water",LOWER(M29)))),"OIL_WATER",IF(ISNUMBER(SEARCH("gas",LOWER(M29))),"GAS",IF(ISNUMBER(SEARCH("water",LOWER(M29))),"WATER",IF(ISNUMBER(SEARCH("oil",LOWER(M29))),"OIL","UNKNOWN"))))))) | R29: =IF(C29="","",C29) | S29: =IF(R29="","",R29+IF(O29<>"",O29,IF(H29="",0,H29))) | T29: =IF(R29="","",MAX(Settings!$B$3,Settings!$B$4*IF(O29<>"",O29,IF(H29="",0,H29)))) | U29: =IF(AND(C29<>"",M29<>"",OR(H29<>"",O29<>"")),"COMPLETE",IF(OR(C29<>"",M29<>""),"PARTIAL","MISSING")) | V29: =IF(Q29="UNKNOWN","Check fluid description",IF(AND(R29<>"",S29<>""),"Ready for contact screening","Needs TVD + thickness"))
Q30: =IF(P30<>"",P30,IF(M30="","UNKNOWN",IF(AND(ISNUMBER(SEARCH("gas",LOWER(M30))),ISNUMBER(SEARCH("water",LOWER(M30)))),"GAS_WATER",IF(AND(ISNUMBER(SEARCH("oil",LOWER(M30))),ISNUMBER(SEARCH("water",LOWER(M30)))),"OIL_WATER",IF(ISNUMBER(SEARCH("gas",LOWER(M30))),"GAS",IF(ISNUMBER(SEARCH("water",LOWER(M30))),"WATER",IF(ISNUMBER(SEARCH("oil",LOWER(M30))),"OIL","UNKNOWN"))))))) | R30: =IF(C30="","",C30) | S30: =IF(R30="","",R30+IF(O30<>"",O30,IF(H30="",0,H30))) | T30: =IF(R30="","",MAX(Settings!$B$3,Settings!$B$4*IF(O30<>"",O30,IF(H30="",0,H30)))) | U30: =IF(AND(C30<>"",M30<>"",OR(H30<>"",O30<>"")),"COMPLETE",IF(OR(C30<>"",M30<>""),"PARTIAL","MISSING")) | V30: =IF(Q30="UNKNOWN","Check fluid description",IF(AND(R30<>"",S30<>""),"Ready for contact screening","Needs TVD + thickness"))
Q31: =IF(P31<>"",P31,IF(M31="","UNKNOWN",IF(AND(ISNUMBER(SEARCH("gas",LOWER(M31))),ISNUMBER(SEARCH("water",LOWER(M31)))),"GAS_WATER",IF(AND(ISNUMBER(SEARCH("oil",LOWER(M31))),ISNUMBER(SEARCH("water",LOWER(M31)))),"OIL_WATER",IF(ISNUMBER(SEARCH("gas",LOWER(M31))),"GAS",IF(ISNUMBER(SEARCH("water",LOWER(M31))),"WATER",IF(ISNUMBER(SEARCH("oil",LOWER(M31))),"OIL","UNKNOWN"))))))) | R31: =IF(C31="","",C31) | S31: =IF(R31="","",R31+IF(O31<>"",O31,IF(H31="",0,H31))) | T31: =IF(R31="","",MAX(Settings!$B$3,Settings!$B$4*IF(O31<>"",O31,IF(H31="",0,H31)))) | U31: =IF(AND(C31<>"",M31<>"",OR(H31<>"",O31<>"")),"COMPLETE",IF(OR(C31<>"",M31<>""),"PARTIAL","MISSING")) | V31: =IF(Q31="UNKNOWN","Check fluid description",IF(AND(R31<>"",S31<>""),"Ready for contact screening","Needs TVD + thickness"))
Q32: =IF(P32<>"",P32,IF(M32="","UNKNOWN",IF(AND(ISNUMBER(SEARCH("gas",LOWER(M32))),ISNUMBER(SEARCH("water",LOWER(M32)))),"GAS_WATER",IF(AND(ISNUMBER(SEARCH("oil",LOWER(M32))),ISNUMBER(SEARCH("water",LOWER(M32)))),"OIL_WATER",IF(ISNUMBER(SEARCH("gas",LOWER(M32))),"GAS",IF(ISNUMBER(SEARCH("water",LOWER(M32))),"WATER",IF(ISNUMBER(SEARCH("oil",LOWER(M32))),"OIL","UNKNOWN"))))))) | R32: =IF(C32="","",C32) | S32: =IF(R32="","",R32+IF(O32<>"",O32,IF(H32="",0,H32))) | T32: =IF(R32="","",MAX(Settings!$B$3,Settings!$B$4*IF(O32<>"",O32,IF(H32="",0,H32)))) | U32: =IF(AND(C32<>"",M32<>"",OR(H32<>"",O32<>"")),"COMPLETE",IF(OR(C32<>"",M32<>""),"PARTIAL","MISSING")) | V32: =IF(Q32="UNKNOWN","Check fluid description",IF(AND(R32<>"",S32<>""),"Ready for contact screening","Needs TVD + thickness"))
Q33: =IF(P33<>"",P33,IF(M33="","UNKNOWN",IF(AND(ISNUMBER(SEARCH("gas",LOWER(M33))),ISNUMBER(SEARCH("water",LOWER(M33)))),"GAS_WATER",IF(AND(ISNUMBER(SEARCH("oil",LOWER(M33))),ISNUMBER(SEARCH("water",LOWER(M33)))),"OIL_WATER",IF(ISNUMBER(SEARCH("gas",LOWER(M33))),"GAS",IF(ISNUMBER(SEARCH("water",LOWER(M33))),"WATER",IF(ISNUMBER(SEARCH("oil",LOWER(M33))),"OIL","UNKNOWN"))))))) | R33: =IF(C33="","",C33) | S33: =IF(R33="","",R33+IF(O33<>"",O33,IF(H33="",0,H33))) | T33: =IF(R33="","",MAX(Settings!$B$3,Settings!$B$4*IF(O33<>"",O33,IF(H33="",0,H33)))) | U33: =IF(AND(C33<>"",M33<>"",OR(H33<>"",O33<>"")),"COMPLETE",IF(OR(C33<>"",M33<>""),"PARTIAL","MISSING")) | V33: =IF(Q33="UNKNOWN","Check fluid description",IF(AND(R33<>"",S33<>""),"Ready for contact screening","Needs TVD + thickness"))
Q34: =IF(P34<>"",P34,IF(M34="","UNKNOWN",IF(AND(ISNUMBER(SEARCH("gas",LOWER(M34))),ISNUMBER(SEARCH("water",LOWER(M34)))),"GAS_WATER",IF(AND(ISNUMBER(SEARCH("oil",LOWER(M34))),ISNUMBER(SEARCH("water",LOWER(M34)))),"OIL_WATER",IF(ISNUMBER(SEARCH("gas",LOWER(M34))),"GAS",IF(ISNUMBER(SEARCH("water",LOWER(M34))),"WATER",IF(ISNUMBER(SEARCH("oil",LOWER(M34))),"OIL","UNKNOWN"))))))) | R34: =IF(C34="","",C34) | S34: =IF(R34="","",R34+IF(O34<>"",O34,IF(H34="",0,H34))) | T34: =IF(R34="","",MAX(Settings!$B$3,Settings!$B$4*IF(O34<>"",O34,IF(H34="",0,H34)))) | U34: =IF(AND(C34<>"",M34<>"",OR(H34<>"",O34<>"")),"COMPLETE",IF(OR(C34<>"",M34<>""),"PARTIAL","MISSING")) | V34: =IF(Q34="UNKNOWN","Check fluid description",IF(AND(R34<>"",S34<>""),"Ready for contact screening","Needs TVD + thickness"))
Q35: =IF(P35<>"",P35,IF(M35="","UNKNOWN",IF(AND(ISNUMBER(SEARCH("gas",LOWER(M35))),ISNUMBER(SEARCH("water",LOWER(M35)))),"GAS_WATER",IF(AND(ISNUMBER(SEARCH("oil",LOWER(M35))),ISNUMBER(SEARCH("water",LOWER(M35)))),"OIL_WATER",IF(ISNUMBER(SEARCH("gas",LOWER(M35))),"GAS",IF(ISNUMBER(SEARCH("water",LOWER(M35))),"WATER",IF(ISNUMBER(SEARCH("oil",LOWER(M35))),"OIL","UNKNOWN"))))))) | R35: =IF(C35="","",C35) | S35: =IF(R35="","",R35+IF(O35<>"",O35,IF(H35="",0,H35))) | T35: =IF(R35="","",MAX(Settings!$B$3,Settings!$B$4*IF(O35<>"",O35,IF(H35="",0,H35)))) | U35: =IF(AND(C35<>"",M35<>"",OR(H35<>"",O35<>"")),"COMPLETE",IF(OR(C35<>"",M35<>""),"PARTIAL","MISSING")) | V35: =IF(Q35="UNKNOWN","Check fluid description",IF(AND(R35<>"",S35<>""),"Ready for contact screening","Needs TVD + thickness"))
Q36: =IF(P36<>"",P36,IF(M36="","UNKNOWN",IF(AND(ISNUMBER(SEARCH("gas",LOWER(M36))),ISNUMBER(SEARCH("water",LOWER(M36)))),"GAS_WATER",IF(AND(ISNUMBER(SEARCH("oil",LOWER(M36))),ISNUMBER(SEARCH("water",LOWER(M36)))),"OIL_WATER",IF(ISNUMBER(SEARCH("gas",LOWER(M36))),"GAS",IF(ISNUMBER(SEARCH("water",LOWER(M36))),"WATER",IF(ISNUMBER(SEARCH("oil",LOWER(M36))),"OIL","UNKNOWN"))))))) | R36: =IF(C36="","",C36) | S36: =IF(R36="","",R36+IF(O36<>"",O36,IF(H36="",0,H36))) | T36: =IF(R36="","",MAX(Settings!$B$3,Settings!$B$4*IF(O36<>"",O36,IF(H36="",0,H36)))) | U36: =IF(AND(C36<>"",M36<>"",OR(H36<>"",O36<>"")),"COMPLETE",IF(OR(C36<>"",M36<>""),"PARTIAL","MISSING")) | V36: =IF(Q36="UNKNOWN","Check fluid description",IF(AND(R36<>"",S36<>""),"Ready for contact screening","Needs TVD + thickness"))
Q37: =IF(P37<>"",P37,IF(M37="","UNKNOWN",IF(AND(ISNUMBER(SEARCH("gas",LOWER(M37))),ISNUMBER(SEARCH("water",LOWER(M37)))),"GAS_WATER",IF(AND(ISNUMBER(SEARCH("oil",LOWER(M37))),ISNUMBER(SEARCH("water",LOWER(M37)))),"OIL_WATER",IF(ISNUMBER(SEARCH("gas",LOWER(M37))),"GAS",IF(ISNUMBER(SEARCH("water",LOWER(M37))),"WATER",IF(ISNUMBER(SEARCH("oil",LOWER(M37))),"OIL","UNKNOWN"))))))) | R37: =IF(C37="","",C37) | S37: =IF(R37="","",R37+IF(O37<>"",O37,IF(H37="",0,H37))) | T37: =IF(R37="","",MAX(Settings!$B$3,Settings!$B$4*IF(O37<>"",O37,IF(H37="",0,H37)))) | U37: =IF(AND(C37<>"",M37<>"",OR(H37<>"",O37<>"")),"COMPLETE",IF(OR(C37<>"",M37<>""),"PARTIAL","MISSING")) | V37: =IF(Q37="UNKNOWN","Check fluid description",IF(AND(R37<>"",S37<>""),"Ready for contact screening","Needs TVD + thickness"))
Q38: =IF(P38<>"",P38,IF(M38="","UNKNOWN",IF(AND(ISNUMBER(SEARCH("gas",LOWER(M38))),ISNUMBER(SEARCH("water",LOWER(M38)))),"GAS_WATER",IF(AND(ISNUMBER(SEARCH("oil",LOWER(M38))),ISNUMBER(SEARCH("water",LOWER(M38)))),"OIL_WATER",IF(ISNUMBER(SEARCH("gas",LOWER(M38))),"GAS",IF(ISNUMBER(SEARCH("water",LOWER(M38))),"WATER",IF(ISNUMBER(SEARCH("oil",LOWER(M38))),"OIL","UNKNOWN"))))))) | R38: =IF(C38="","",C38) | S38: =IF(R38="","",R38+IF(O38<>"",O38,IF(H38="",0,H38))) | T38: =IF(R38="","",MAX(Settings!$B$3,Settings!$B$4*IF(O38<>"",O38,IF(H38="",0,H38)))) | U38: =IF(AND(C38<>"",M38<>"",OR(H38<>"",O38<>"")),"COMPLETE",IF(OR(C38<>"",M38<>""),"PARTIAL","MISSING")) | V38: =IF(Q38="UNKNOWN","Check fluid description",IF(AND(R38<>"",S38<>""),"Ready for contact screening","Needs TVD + thickness"))
Q39: =IF(P39<>"",P39,IF(M39="","UNKNOWN",IF(AND(ISNUMBER(SEARCH("gas",LOWER(M39))),ISNUMBER(SEARCH("water",LOWER(M39)))),"GAS_WATER",IF(AND(ISNUMBER(SEARCH("oil",LOWER(M39))),ISNUMBER(SEARCH("water",LOWER(M39)))),"OIL_WATER",IF(ISNUMBER(SEARCH("gas",LOWER(M39))),"GAS",IF(ISNUMBER(SEARCH("water",LOWER(M39))),"WATER",IF(ISNUMBER(SEARCH("oil",LOWER(M39))),"OIL","UNKNOWN"))))))) | R39: =IF(C39="","",C39) | S39: =IF(R39="","",R39+IF(O39<>"",O39,IF(H39="",0,H39))) | T39: =IF(R39="","",MAX(Settings!$B$3,Settings!$B$4*IF(O39<>"",O39,IF(H39="",0,H39)))) | U39: =IF(AND(C39<>"",M39<>"",OR(H39<>"",O39<>"")),"COMPLETE",IF(OR(C39<>"",M39<>""),"PARTIAL","MISSING")) | V39: =IF(Q39="UNKNOWN","Check fluid description",IF(AND(R39<>"",S39<>""),"Ready for contact screening","Needs TVD + thickness"))
Q40: =IF(P40<>"",P40,IF(M40="","UNKNOWN",IF(AND(ISNUMBER(SEARCH("gas",LOWER(M40))),ISNUMBER(SEARCH("water",LOWER(M40)))),"GAS_WATER",IF(AND(ISNUMBER(SEARCH("oil",LOWER(M40))),ISNUMBER(SEARCH("water",LOWER(M40)))),"OIL_WATER",IF(ISNUMBER(SEARCH("gas",LOWER(M40))),"GAS",IF(ISNUMBER(SEARCH("water",LOWER(M40))),"WATER",IF(ISNUMBER(SEARCH("oil",LOWER(M40))),"OIL","UNKNOWN"))))))) | R40: =IF(C40="","",C40) | S40: =IF(R40="","",R40+IF(O40<>"",O40,IF(H40="",0,H40))) | T40: =IF(R40="","",MAX(Settings!$B$3,Settings!$B$4*IF(O40<>"",O40,IF(H40="",0,H40)))) | U40: =IF(AND(C40<>"",M40<>"",OR(H40<>"",O40<>"")),"COMPLETE",IF(OR(C40<>"",M40<>""),"PARTIAL","MISSING")) | V40: =IF(Q40="UNKNOWN","Check fluid description",IF(AND(R40<>"",S40<>""),"Ready for contact screening","Needs TVD + thickness"))
Q41: =IF(P41<>"",P41,IF(M41="","UNKNOWN",IF(AND(ISNUMBER(SEARCH("gas",LOWER(M41))),ISNUMBER(SEARCH("water",LOWER(M41)))),"GAS_WATER",IF(AND(ISNUMBER(SEARCH("oil",LOWER(M41))),ISNUMBER(SEARCH("water",LOWER(M41)))),"OIL_WATER",IF(ISNUMBER(SEARCH("gas",LOWER(M41))),"GAS",IF(ISNUMBER(SEARCH("water",LOWER(M41))),"WATER",IF(ISNUMBER(SEARCH("oil",LOWER(M41))),"OIL","UNKNOWN"))))))) | R41: =IF(C41="","",C41) | S41: =IF(R41="","",R41+IF(O41<>"",O41,IF(H41="",0,H41))) | T41: =IF(R41="","",MAX(Settings!$B$3,Settings!$B$4*IF(O41<>"",O41,IF(H41="",0,H41)))) | U41: =IF(AND(C41<>"",M41<>"",OR(H41<>"",O41<>"")),"COMPLETE",IF(OR(C41<>"",M41<>""),"PARTIAL","MISSING")) | V41: =IF(Q41="UNKNOWN","Check fluid description",IF(AND(R41<>"",S41<>""),"Ready for contact screening","Needs TVD + thickness"))
... Q1001: =IF(P1001<>"",P1001,IF(M1001="","UNKNOWN",IF(AND(ISNUMBER(SEARCH("gas",LOWER(M1001))),ISNUMBER(SEARCH("water",LOWER(M1001)))),"GAS_WATER",IF(AND(ISNUMBER(SEARCH("oil",LOWER(M1001))),ISNUMBER(SEARCH("water",LOWER(M1001)))),"OIL_WATER",IF(ISNUMBER(SEARCH("gas",LOWER(M1001))),"GAS",IF(ISNUMBER(SEARCH("water",LOWER(M1001))),"WATER",IF(ISNUMBER(SEARCH("oil",LOWER(M1001))),"OIL","UNKNOWN"))))))) | R1001: =IF(C1001="","",C1001) | S1001: =IF(R1001="","",R1001+IF(O1001<>"",O1001,IF(H1001="",0,H1001))) | T1001: =IF(R1001="","",MAX(Settings!$B$3,Settings!$B$4*IF(O1001<>"",O1001,IF(H1001="",0,H1001)))) | U1001: =IF(AND(C1001<>"",M1001<>"",OR(H1001<>"",O1001<>"")),"COMPLETE",IF(OR(C1001<>"",M1001<>""),"PARTIAL","MISSING")) | V1001: =IF(Q1001="UNKNOWN","Check fluid description",IF(AND(R1001<>"",S1001<>""),"Ready for contact screening","Needs TVD + thickness"))

Sheet Settings
A1: FLUID CONTACT DETECTOR — SETTINGS
A3: Parameter | B3: Value | C3: Unit | D3: Purpose
A4: Minimum contact uncertainty | B4: 5 | C4: m | D4: Lower bound of screening envelope
A5: Uncertainty fraction | B5: 0.03 | C5: fraction | D5: Screening envelope = MAX(minimum, fraction × effective thickness)
A6: Direct transition weight | B6: 0.6 | C6: weight | D6: Weight for direct fluid-class transition
A7: Sw consistency weight | B7: 0.2 | C7: weight | D7: Weight for saturation-direction support
A8: Data completeness weight | B8: 0.2 | C8: weight | D8: Weight for depth/thickness/fluid completeness
A11: Fluid classification logic
A12: GAS | B12: Fluids text contains gas and not water.
A13: OIL | B13: Fluids text contains oil and not water; includes low-concentration/swept-oil descriptions.
A14: OIL_WATER | B14: Fluids text contains both oil and water.
A15: GAS_WATER | B15: Fluids text contains both gas and water.
A16: WATER | B16: Fluids text contains water and not oil/gas.
A17: Fluid_Override | B17: Use this only when the automatic text classification is not appropriate.
A20: Research basis
A21: The detector follows the supplied CHIRAG FLOWSCAPE methodology: formation-specific fluids are preserved; original/shifted contacts are separated; contact uncertainty is propagated; permeability is not treated as connectivity by itself; and static evidence is treated as a prior that can later be updated with dynamic evidence.

Sheet Contact_Detector
A1: Well | B1: Upper Formation | C1: Lower Formation | D1: Upper Fluid | E1: Lower Fluid | F1: Contact_Type | G1: Candidate_Contact_TVD | H1: Uncertainty_m | I1: Low_TVD | J1: High_TVD | K1: Upper_Sw | L1: Lower_Sw | M1: Delta_Sw | N1: Sw_Check | O1: Contact_Screening_Score | P1: Evidence_Flag | Q1: Action / Interpretation
A2: =IF(AND(Master_Data!A2<>"",Master_Data!A2=Master_Data!A3),Master_Data!A2,"") | B2: =IF($A2="","",Master_Data!B2) | C2: =IF($A2="","",Master_Data!B3) | D2: =IF($A2="","",Master_Data!Q2) | E2: =IF($A2="","",Master_Data!Q3) | F2: =IF($A2="","",IF(AND(D2="GAS",E2="OIL"),"GOC",IF(AND(D2="OIL",E2="WATER"),"OWC",IF(AND(D2="GAS",E2="WATER"),"GWC",IF(AND(D2="OIL",E2="OIL_WATER"),"OWC_TRANSITION",IF(AND(D2="OIL_WATER",E2="WATER"),"OWC_TRANSITION",IF(AND(D2="GAS",E2="GAS_WATER"),"GOC_TRANSITION",IF(AND(D2="GAS_WATER",E2="OIL"),"GOC_TRANSITION",IF(OR(D2="OIL_WATER",D2="GAS_WATER"),"TRANSITION_INTERVAL",""))))))))) | G2: =IF(OR(F2="",Master_Data!R2="",Master_Data!S2=""),"",IF(RIGHT(F2,10)="TRANSITION",AVERAGE(Master_Data!R2:Master_Data!S2),AVERAGE(Master_Data!S2,Master_Data!R3))) | H2: =IF(G2="","",MAX(Settings!$B$4,Settings!$B$5*AVERAGE(IF(Master_Data!O2<>"",Master_Data!O2,Master_Data!H2),IF(Master_Data!O3<>"",Master_Data!O3,Master_Data!H3)))) | I2: =IF(G2="","",G2-H2) | J2: =IF(G2="","",G2+H2) | K2: =IF($A2="","",Master_Data!G2) | L2: =IF($A2="","",Master_Data!G3) | M2: =IF(AND(ISNUMBER(K2),ISNUMBER(L2)),L2-K2,"") | N2: =IF(G2="","",IF(AND(ISNUMBER(K2),ISNUMBER(L2)),IF(OR(F2="GOC",F2="OWC",F2="GWC",F2="OWC_TRANSITION",F2="GOC_TRANSITION"),IF(L2>=K2,"Supports","Conflicts"),"N/A"),"No Sw")) | O2: =IF(G2="","",Settings!$B$6*IF(OR(F2="GOC",F2="OWC",F2="GWC"),1,0.7)+Settings!$B$7*IF(N2="Supports",1,IF(N2="Conflicts",0,0.5))+Settings!$B$8*IF(AND(Master_Data!R2<>"",Master_Data!S2<>"",Master_Data!R3<>"",Master_Data!S3<>""),1,0.5)) | P2: =IF(G2="","",IF(N2="Conflicts","SW_CONFLICT",IF(OR(F2="GOC",F2="OWC",F2="GWC"),"DIRECT_FLUID_TRANSITION","TRANSITION_INTERVAL"))) | Q2: =IF(G2="","",IF(N2="Conflicts","Investigate contact interpretation / saturation behaviour",IF(OR(F2="OWC",F2="GOC",F2="GWC"),"Candidate contact — validate with logs, pressure and dynamic evidence","Transition zone — do not force to a sharp contact")))
A3: =IF(AND(Master_Data!A3<>"",Master_Data!A3=Master_Data!A4),Master_Data!A3,"") | B3: =IF($A3="","",Master_Data!B3) | C3: =IF($A3="","",Master_Data!B4) | D3: =IF($A3="","",Master_Data!Q3) | E3: =IF($A3="","",Master_Data!Q4) | F3: =IF($A3="","",IF(AND(D3="GAS",E3="OIL"),"GOC",IF(AND(D3="OIL",E3="WATER"),"OWC",IF(AND(D3="GAS",E3="WATER"),"GWC",IF(AND(D3="OIL",E3="OIL_WATER"),"OWC_TRANSITION",IF(AND(D3="OIL_WATER",E3="WATER"),"OWC_TRANSITION",IF(AND(D3="GAS",E3="GAS_WATER"),"GOC_TRANSITION",IF(AND(D3="GAS_WATER",E3="OIL"),"GOC_TRANSITION",IF(OR(D3="OIL_WATER",D3="GAS_WATER"),"TRANSITION_INTERVAL",""))))))))) | G3: =IF(OR(F3="",Master_Data!R3="",Master_Data!S3=""),"",IF(RIGHT(F3,10)="TRANSITION",AVERAGE(Master_Data!R3:Master_Data!S3),AVERAGE(Master_Data!S3,Master_Data!R4))) | H3: =IF(G3="","",MAX(Settings!$B$4,Settings!$B$5*AVERAGE(IF(Master_Data!O3<>"",Master_Data!O3,Master_Data!H3),IF(Master_Data!O4<>"",Master_Data!O4,Master_Data!H4)))) | I3: =IF(G3="","",G3-H3) | J3: =IF(G3="","",G3+H3) | K3: =IF($A3="","",Master_Data!G3) | L3: =IF($A3="","",Master_Data!G4) | M3: =IF(AND(ISNUMBER(K3),ISNUMBER(L3)),L3-K3,"") | N3: =IF(G3="","",IF(AND(ISNUMBER(K3),ISNUMBER(L3)),IF(OR(F3="GOC",F3="OWC",F3="GWC",F3="OWC_TRANSITION",F3="GOC_TRANSITION"),IF(L3>=K3,"Supports","Conflicts"),"N/A"),"No Sw")) | O3: =IF(G3="","",Settings!$B$6*IF(OR(F3="GOC",F3="OWC",F3="GWC"),1,0.7)+Settings!$B$7*IF(N3="Supports",1,IF(N3="Conflicts",0,0.5))+Settings!$B$8*IF(AND(Master_Data!R3<>"",Master_Data!S3<>"",Master_Data!R4<>"",Master_Data!S4<>""),1,0.5)) | P3: =IF(G3="","",IF(N3="Conflicts","SW_CONFLICT",IF(OR(F3="GOC",F3="OWC",F3="GWC"),"DIRECT_FLUID_TRANSITION","TRANSITION_INTERVAL"))) | Q3: =IF(G3="","",IF(N3="Conflicts","Investigate contact interpretation / saturation behaviour",IF(OR(F3="OWC",F3="GOC",F3="GWC"),"Candidate contact — validate with logs, pressure and dynamic evidence","Transition zone — do not force to a sharp contact")))
A4: =IF(AND(Master_Data!A4<>"",Master_Data!A4=Master_Data!A5),Master_Data!A4,"") | B4: =IF($A4="","",Master_Data!B4) | C4: =IF($A4="","",Master_Data!B5) | D4: =IF($A4="","",Master_Data!Q4) | E4: =IF($A4="","",Master_Data!Q5) | F4: =IF($A4="","",IF(AND(D4="GAS",E4="OIL"),"GOC",IF(AND(D4="OIL",E4="WATER"),"OWC",IF(AND(D4="GAS",E4="WATER"),"GWC",IF(AND(D4="OIL",E4="OIL_WATER"),"OWC_TRANSITION",IF(AND(D4="OIL_WATER",E4="WATER"),"OWC_TRANSITION",IF(AND(D4="GAS",E4="GAS_WATER"),"GOC_TRANSITION",IF(AND(D4="GAS_WATER",E4="OIL"),"GOC_TRANSITION",IF(OR(D4="OIL_WATER",D4="GAS_WATER"),"TRANSITION_INTERVAL",""))))))))) | G4: =IF(OR(F4="",Master_Data!R4="",Master_Data!S4=""),"",IF(RIGHT(F4,10)="TRANSITION",AVERAGE(Master_Data!R4:Master_Data!S4),AVERAGE(Master_Data!S4,Master_Data!R5))) | H4: =IF(G4="","",MAX(Settings!$B$4,Settings!$B$5*AVERAGE(IF(Master_Data!O4<>"",Master_Data!O4,Master_Data!H4),IF(Master_Data!O5<>"",Master_Data!O5,Master_Data!H5)))) | I4: =IF(G4="","",G4-H4) | J4: =IF(G4="","",G4+H4) | K4: =IF($A4="","",Master_Data!G4) | L4: =IF($A4="","",Master_Data!G5) | M4: =IF(AND(ISNUMBER(K4),ISNUMBER(L4)),L4-K4,"") | N4: =IF(G4="","",IF(AND(ISNUMBER(K4),ISNUMBER(L4)),IF(OR(F4="GOC",F4="OWC",F4="GWC",F4="OWC_TRANSITION",F4="GOC_TRANSITION"),IF(L4>=K4,"Supports","Conflicts"),"N/A"),"No Sw")) | O4: =IF(G4="","",Settings!$B$6*IF(OR(F4="GOC",F4="OWC",F4="GWC"),1,0.7)+Settings!$B$7*IF(N4="Supports",1,IF(N4="Conflicts",0,0.5))+Settings!$B$8*IF(AND(Master_Data!R4<>"",Master_Data!S4<>"",Master_Data!R5<>"",Master_Data!S5<>""),1,0.5)) | P4: =IF(G4="","",IF(N4="Conflicts","SW_CONFLICT",IF(OR(F4="GOC",F4="OWC",F4="GWC"),"DIRECT_FLUID_TRANSITION","TRANSITION_INTERVAL"))) | Q4: =IF(G4="","",IF(N4="Conflicts","Investigate contact interpretation / saturation behaviour",IF(OR(F4="OWC",F4="GOC",F4="GWC"),"Candidate contact — validate with logs, pressure and dynamic evidence","Transition zone — do not force to a sharp contact")))
A5: =IF(AND(Master_Data!A5<>"",Master_Data!A5=Master_Data!A6),Master_Data!A5,"") | B5: =IF($A5="","",Master_Data!B5) | C5: =IF($A5="","",Master_Data!B6) | D5: =IF($A5="","",Master_Data!Q5) | E5: =IF($A5="","",Master_Data!Q6) | F5: =IF($A5="","",IF(AND(D5="GAS",E5="OIL"),"GOC",IF(AND(D5="OIL",E5="WATER"),"OWC",IF(AND(D5="GAS",E5="WATER"),"GWC",IF(AND(D5="OIL",E5="OIL_WATER"),"OWC_TRANSITION",IF(AND(D5="OIL_WATER",E5="WATER"),"OWC_TRANSITION",IF(AND(D5="GAS",E5="GAS_WATER"),"GOC_TRANSITION",IF(AND(D5="GAS_WATER",E5="OIL"),"GOC_TRANSITION",IF(OR(D5="OIL_WATER",D5="GAS_WATER"),"TRANSITION_INTERVAL",""))))))))) | G5: =IF(OR(F5="",Master_Data!R5="",Master_Data!S5=""),"",IF(RIGHT(F5,10)="TRANSITION",AVERAGE(Master_Data!R5:Master_Data!S5),AVERAGE(Master_Data!S5,Master_Data!R6))) | H5: =IF(G5="","",MAX(Settings!$B$4,Settings!$B$5*AVERAGE(IF(Master_Data!O5<>"",Master_Data!O5,Master_Data!H5),IF(Master_Data!O6<>"",Master_Data!O6,Master_Data!H6)))) | I5: =IF(G5="","",G5-H5) | J5: =IF(G5="","",G5+H5) | K5: =IF($A5="","",Master_Data!G5) | L5: =IF($A5="","",Master_Data!G6) | M5: =IF(AND(ISNUMBER(K5),ISNUMBER(L5)),L5-K5,"") | N5: =IF(G5="","",IF(AND(ISNUMBER(K5),ISNUMBER(L5)),IF(OR(F5="GOC",F5="OWC",F5="GWC",F5="OWC_TRANSITION",F5="GOC_TRANSITION"),IF(L5>=K5,"Supports","Conflicts"),"N/A"),"No Sw")) | O5: =IF(G5="","",Settings!$B$6*IF(OR(F5="GOC",F5="OWC",F5="GWC"),1,0.7)+Settings!$B$7*IF(N5="Supports",1,IF(N5="Conflicts",0,0.5))+Settings!$B$8*IF(AND(Master_Data!R5<>"",Master_Data!S5<>"",Master_Data!R6<>"",Master_Data!S6<>""),1,0.5)) | P5: =IF(G5="","",IF(N5="Conflicts","SW_CONFLICT",IF(OR(F5="GOC",F5="OWC",F5="GWC"),"DIRECT_FLUID_TRANSITION","TRANSITION_INTERVAL"))) | Q5: =IF(G5="","",IF(N5="Conflicts","Investigate contact interpretation / saturation behaviour",IF(OR(F5="OWC",F5="GOC",F5="GWC"),"Candidate contact — validate with logs, pressure and dynamic evidence","Transition zone — do not force to a sharp contact")))
A6: =IF(AND(Master_Data!A6<>"",Master_Data!A6=Master_Data!A7),Master_Data!A6,"") | B6: =IF($A6="","",Master_Data!B6) | C6: =IF($A6="","",Master_Data!B7) | D6: =IF($A6="","",Master_Data!Q6) | E6: =IF($A6="","",Master_Data!Q7) | F6: =IF($A6="","",IF(AND(D6="GAS",E6="OIL"),"GOC",IF(AND(D6="OIL",E6="WATER"),"OWC",IF(AND(D6="GAS",E6="WATER"),"GWC",IF(AND(D6="OIL",E6="OIL_WATER"),"OWC_TRANSITION",IF(AND(D6="OIL_WATER",E6="WATER"),"OWC_TRANSITION",IF(AND(D6="GAS",E6="GAS_WATER"),"GOC_TRANSITION",IF(AND(D6="GAS_WATER",E6="OIL"),"GOC_TRANSITION",IF(OR(D6="OIL_WATER",D6="GAS_WATER"),"TRANSITION_INTERVAL",""))))))))) | G6: =IF(OR(F6="",Master_Data!R6="",Master_Data!S6=""),"",IF(RIGHT(F6,10)="TRANSITION",AVERAGE(Master_Data!R6:Master_Data!S6),AVERAGE(Master_Data!S6,Master_Data!R7))) | H6: =IF(G6="","",MAX(Settings!$B$4,Settings!$B$5*AVERAGE(IF(Master_Data!O6<>"",Master_Data!O6,Master_Data!H6),IF(Master_Data!O7<>"",Master_Data!O7,Master_Data!H7)))) | I6: =IF(G6="","",G6-H6) | J6: =IF(G6="","",G6+H6) | K6: =IF($A6="","",Master_Data!G6) | L6: =IF($A6="","",Master_Data!G7) | M6: =IF(AND(ISNUMBER(K6),ISNUMBER(L6)),L6-K6,"") | N6: =IF(G6="","",IF(AND(ISNUMBER(K6),ISNUMBER(L6)),IF(OR(F6="GOC",F6="OWC",F6="GWC",F6="OWC_TRANSITION",F6="GOC_TRANSITION"),IF(L6>=K6,"Supports","Conflicts"),"N/A"),"No Sw")) | O6: =IF(G6="","",Settings!$B$6*IF(OR(F6="GOC",F6="OWC",F6="GWC"),1,0.7)+Settings!$B$7*IF(N6="Supports",1,IF(N6="Conflicts",0,0.5))+Settings!$B$8*IF(AND(Master_Data!R6<>"",Master_Data!S6<>"",Master_Data!R7<>"",Master_Data!S7<>""),1,0.5)) | P6: =IF(G6="","",IF(N6="Conflicts","SW_CONFLICT",IF(OR(F6="GOC",F6="OWC",F6="GWC"),"DIRECT_FLUID_TRANSITION","TRANSITION_INTERVAL"))) | Q6: =IF(G6="","",IF(N6="Conflicts","Investigate contact interpretation / saturation behaviour",IF(OR(F6="OWC",F6="GOC",F6="GWC"),"Candidate contact — validate with logs, pressure and dynamic evidence","Transition zone — do not force to a sharp contact")))
A7: =IF(AND(Master_Data!A7<>"",Master_Data!A7=Master_Data!A8),Master_Data!A7,"") | B7: =IF($A7="","",Master_Data!B7) | C7: =IF($A7="","",Master_Data!B8) | D7: =IF($A7="","",Master_Data!Q7) | E7: =IF($A7="","",Master_Data!Q8) | F7: =IF($A7="","",IF(AND(D7="GAS",E7="OIL"),"GOC",IF(AND(D7="OIL",E7="WATER"),"OWC",IF(AND(D7="GAS",E7="WATER"),"GWC",IF(AND(D7="OIL",E7="OIL_WATER"),"OWC_TRANSITION",IF(AND(D7="OIL_WATER",E7="WATER"),"OWC_TRANSITION",IF(AND(D7="GAS",E7="GAS_WATER"),"GOC_TRANSITION",IF(AND(D7="GAS_WATER",E7="OIL"),"GOC_TRANSITION",IF(OR(D7="OIL_WATER",D7="GAS_WATER"),"TRANSITION_INTERVAL",""))))))))) | G7: =IF(OR(F7="",Master_Data!R7="",Master_Data!S7=""),"",IF(RIGHT(F7,10)="TRANSITION",AVERAGE(Master_Data!R7:Master_Data!S7),AVERAGE(Master_Data!S7,Master_Data!R8))) | H7: =IF(G7="","",MAX(Settings!$B$4,Settings!$B$5*AVERAGE(IF(Master_Data!O7<>"",Master_Data!O7,Master_Data!H7),IF(Master_Data!O8<>"",Master_Data!O8,Master_Data!H8)))) | I7: =IF(G7="","",G7-H7) | J7: =IF(G7="","",G7+H7) | K7: =IF($A7="","",Master_Data!G7) | L7: =IF($A7="","",Master_Data!G8) | M7: =IF(AND(ISNUMBER(K7),ISNUMBER(L7)),L7-K7,"") | N7: =IF(G7="","",IF(AND(ISNUMBER(K7),ISNUMBER(L7)),IF(OR(F7="GOC",F7="OWC",F7="GWC",F7="OWC_TRANSITION",F7="GOC_TRANSITION"),IF(L7>=K7,"Supports","Conflicts"),"N/A"),"No Sw")) | O7: =IF(G7="","",Settings!$B$6*IF(OR(F7="GOC",F7="OWC",F7="GWC"),1,0.7)+Settings!$B$7*IF(N7="Supports",1,IF(N7="Conflicts",0,0.5))+Settings!$B$8*IF(AND(Master_Data!R7<>"",Master_Data!S7<>"",Master_Data!R8<>"",Master_Data!S8<>""),1,0.5)) | P7: =IF(G7="","",IF(N7="Conflicts","SW_CONFLICT",IF(OR(F7="GOC",F7="OWC",F7="GWC"),"DIRECT_FLUID_TRANSITION","TRANSITION_INTERVAL"))) | Q7: =IF(G7="","",IF(N7="Conflicts","Investigate contact interpretation / saturation behaviour",IF(OR(F7="OWC",F7="GOC",F7="GWC"),"Candidate contact — validate with logs, pressure and dynamic evidence","Transition zone — do not force to a sharp contact")))
A8: =IF(AND(Master_Data!A8<>"",Master_Data!A8=Master_Data!A9),Master_Data!A8,"") | B8: =IF($A8="","",Master_Data!B8) | C8: =IF($A8="","",Master_Data!B9) | D8: =IF($A8="","",Master_Data!Q8) | E8: =IF($A8="","",Master_Data!Q9) | F8: =IF($A8="","",IF(AND(D8="GAS",E8="OIL"),"GOC",IF(AND(D8="OIL",E8="WATER"),"OWC",IF(AND(D8="GAS",E8="WATER"),"GWC",IF(AND(D8="OIL",E8="OIL_WATER"),"OWC_TRANSITION",IF(AND(D8="OIL_WATER",E8="WATER"),"OWC_TRANSITION",IF(AND(D8="GAS",E8="GAS_WATER"),"GOC_TRANSITION",IF(AND(D8="GAS_WATER",E8="OIL"),"GOC_TRANSITION",IF(OR(D8="OIL_WATER",D8="GAS_WATER"),"TRANSITION_INTERVAL",""))))))))) | G8: =IF(OR(F8="",Master_Data!R8="",Master_Data!S8=""),"",IF(RIGHT(F8,10)="TRANSITION",AVERAGE(Master_Data!R8:Master_Data!S8),AVERAGE(Master_Data!S8,Master_Data!R9))) | H8: =IF(G8="","",MAX(Settings!$B$4,Settings!$B$5*AVERAGE(IF(Master_Data!O8<>"",Master_Data!O8,Master_Data!H8),IF(Master_Data!O9<>"",Master_Data!O9,Master_Data!H9)))) | I8: =IF(G8="","",G8-H8) | J8: =IF(G8="","",G8+H8) | K8: =IF($A8="","",Master_Data!G8) | L8: =IF($A8="","",Master_Data!G9) | M8: =IF(AND(ISNUMBER(K8),ISNUMBER(L8)),L8-K8,"") | N8: =IF(G8="","",IF(AND(ISNUMBER(K8),ISNUMBER(L8)),IF(OR(F8="GOC",F8="OWC",F8="GWC",F8="OWC_TRANSITION",F8="GOC_TRANSITION"),IF(L8>=K8,"Supports","Conflicts"),"N/A"),"No Sw")) | O8: =IF(G8="","",Settings!$B$6*IF(OR(F8="GOC",F8="OWC",F8="GWC"),1,0.7)+Settings!$B$7*IF(N8="Supports",1,IF(N8="Conflicts",0,0.5))+Settings!$B$8*IF(AND(Master_Data!R8<>"",Master_Data!S8<>"",Master_Data!R9<>"",Master_Data!S9<>""),1,0.5)) | P8: =IF(G8="","",IF(N8="Conflicts","SW_CONFLICT",IF(OR(F8="GOC",F8="OWC",F8="GWC"),"DIRECT_FLUID_TRANSITION","TRANSITION_INTERVAL"))) | Q8: =IF(G8="","",IF(N8="Conflicts","Investigate contact interpretation / saturation behaviour",IF(OR(F8="OWC",F8="GOC",F8="GWC"),"Candidate contact — validate with logs, pressure and dynamic evidence","Transition zone — do not force to a sharp contact")))
A9: =IF(AND(Master_Data!A9<>"",Master_Data!A9=Master_Data!A10),Master_Data!A9,"") | B9: =IF($A9="","",Master_Data!B9) | C9: =IF($A9="","",Master_Data!B10) | D9: =IF($A9="","",Master_Data!Q9) | E9: =IF($A9="","",Master_Data!Q10) | F9: =IF($A9="","",IF(AND(D9="GAS",E9="OIL"),"GOC",IF(AND(D9="OIL",E9="WATER"),"OWC",IF(AND(D9="GAS",E9="WATER"),"GWC",IF(AND(D9="OIL",E9="OIL_WATER"),"OWC_TRANSITION",IF(AND(D9="OIL_WATER",E9="WATER"),"OWC_TRANSITION",IF(AND(D9="GAS",E9="GAS_WATER"),"GOC_TRANSITION",IF(AND(D9="GAS_WATER",E9="OIL"),"GOC_TRANSITION",IF(OR(D9="OIL_WATER",D9="GAS_WATER"),"TRANSITION_INTERVAL",""))))))))) | G9: =IF(OR(F9="",Master_Data!R9="",Master_Data!S9=""),"",IF(RIGHT(F9,10)="TRANSITION",AVERAGE(Master_Data!R9:Master_Data!S9),AVERAGE(Master_Data!S9,Master_Data!R10))) | H9: =IF(G9="","",MAX(Settings!$B$4,Settings!$B$5*AVERAGE(IF(Master_Data!O9<>"",Master_Data!O9,Master_Data!H9),IF(Master_Data!O10<>"",Master_Data!O10,Master_Data!H10)))) | I9: =IF(G9="","",G9-H9) | J9: =IF(G9="","",G9+H9) | K9: =IF($A9="","",Master_Data!G9) | L9: =IF($A9="","",Master_Data!G10) | M9: =IF(AND(ISNUMBER(K9),ISNUMBER(L9)),L9-K9,"") | N9: =IF(G9="","",IF(AND(ISNUMBER(K9),ISNUMBER(L9)),IF(OR(F9="GOC",F9="OWC",F9="GWC",F9="OWC_TRANSITION",F9="GOC_TRANSITION"),IF(L9>=K9,"Supports","Conflicts"),"N/A"),"No Sw")) | O9: =IF(G9="","",Settings!$B$6*IF(OR(F9="GOC",F9="OWC",F9="GWC"),1,0.7)+Settings!$B$7*IF(N9="Supports",1,IF(N9="Conflicts",0,0.5))+Settings!$B$8*IF(AND(Master_Data!R9<>"",Master_Data!S9<>"",Master_Data!R10<>"",Master_Data!S10<>""),1,0.5)) | P9: =IF(G9="","",IF(N9="Conflicts","SW_CONFLICT",IF(OR(F9="GOC",F9="OWC",F9="GWC"),"DIRECT_FLUID_TRANSITION","TRANSITION_INTERVAL"))) | Q9: =IF(G9="","",IF(N9="Conflicts","Investigate contact interpretation / saturation behaviour",IF(OR(F9="OWC",F9="GOC",F9="GWC"),"Candidate contact — validate with logs, pressure and dynamic evidence","Transition zone — do not force to a sharp contact")))
A10: =IF(AND(Master_Data!A10<>"",Master_Data!A10=Master_Data!A11),Master_Data!A10,"") | B10: =IF($A10="","",Master_Data!B10) | C10: =IF($A10="","",Master_Data!B11) | D10: =IF($A10="","",Master_Data!Q10) | E10: =IF($A10="","",Master_Data!Q11) | F10: =IF($A10="","",IF(AND(D10="GAS",E10="OIL"),"GOC",IF(AND(D10="OIL",E10="WATER"),"OWC",IF(AND(D10="GAS",E10="WATER"),"GWC",IF(AND(D10="OIL",E10="OIL_WATER"),"OWC_TRANSITION",IF(AND(D10="OIL_WATER",E10="WATER"),"OWC_TRANSITION",IF(AND(D10="GAS",E10="GAS_WATER"),"GOC_TRANSITION",IF(AND(D10="GAS_WATER",E10="OIL"),"GOC_TRANSITION",IF(OR(D10="OIL_WATER",D10="GAS_WATER"),"TRANSITION_INTERVAL",""))))))))) | G10: =IF(OR(F10="",Master_Data!R10="",Master_Data!S10=""),"",IF(RIGHT(F10,10)="TRANSITION",AVERAGE(Master_Data!R10:Master_Data!S10),AVERAGE(Master_Data!S10,Master_Data!R11))) | H10: =IF(G10="","",MAX(Settings!$B$4,Settings!$B$5*AVERAGE(IF(Master_Data!O10<>"",Master_Data!O10,Master_Data!H10),IF(Master_Data!O11<>"",Master_Data!O11,Master_Data!H11)))) | I10: =IF(G10="","",G10-H10) | J10: =IF(G10="","",G10+H10) | K10: =IF($A10="","",Master_Data!G10) | L10: =IF($A10="","",Master_Data!G11) | M10: =IF(AND(ISNUMBER(K10),ISNUMBER(L10)),L10-K10,"") | N10: =IF(G10="","",IF(AND(ISNUMBER(K10),ISNUMBER(L10)),IF(OR(F10="GOC",F10="OWC",F10="GWC",F10="OWC_TRANSITION",F10="GOC_TRANSITION"),IF(L10>=K10,"Supports","Conflicts"),"N/A"),"No Sw")) | O10: =IF(G10="","",Settings!$B$6*IF(OR(F10="GOC",F10="OWC",F10="GWC"),1,0.7)+Settings!$B$7*IF(N10="Supports",1,IF(N10="Conflicts",0,0.5))+Settings!$B$8*IF(AND(Master_Data!R10<>"",Master_Data!S10<>"",Master_Data!R11<>"",Master_Data!S11<>""),1,0.5)) | P10: =IF(G10="","",IF(N10="Conflicts","SW_CONFLICT",IF(OR(F10="GOC",F10="OWC",F10="GWC"),"DIRECT_FLUID_TRANSITION","TRANSITION_INTERVAL"))) | Q10: =IF(G10="","",IF(N10="Conflicts","Investigate contact interpretation / saturation behaviour",IF(OR(F10="OWC",F10="GOC",F10="GWC"),"Candidate contact — validate with logs, pressure and dynamic evidence","Transition zone — do not force to a sharp contact")))
A11: =IF(AND(Master_Data!A11<>"",Master_Data!A11=Master_Data!A12),Master_Data!A11,"") | B11: =IF($A11="","",Master_Data!B11) | C11: =IF($A11="","",Master_Data!B12) | D11: =IF($A11="","",Master_Data!Q11) | E11: =IF($A11="","",Master_Data!Q12) | F11: =IF($A11="","",IF(AND(D11="GAS",E11="OIL"),"GOC",IF(AND(D11="OIL",E11="WATER"),"OWC",IF(AND(D11="GAS",E11="WATER"),"GWC",IF(AND(D11="OIL",E11="OIL_WATER"),"OWC_TRANSITION",IF(AND(D11="OIL_WATER",E11="WATER"),"OWC_TRANSITION",IF(AND(D11="GAS",E11="GAS_WATER"),"GOC_TRANSITION",IF(AND(D11="GAS_WATER",E11="OIL"),"GOC_TRANSITION",IF(OR(D11="OIL_WATER",D11="GAS_WATER"),"TRANSITION_INTERVAL",""))))))))) | G11: =IF(OR(F11="",Master_Data!R11="",Master_Data!S11=""),"",IF(RIGHT(F11,10)="TRANSITION",AVERAGE(Master_Data!R11:Master_Data!S11),AVERAGE(Master_Data!S11,Master_Data!R12))) | H11: =IF(G11="","",MAX(Settings!$B$4,Settings!$B$5*AVERAGE(IF(Master_Data!O11<>"",Master_Data!O11,Master_Data!H11),IF(Master_Data!O12<>"",Master_Data!O12,Master_Data!H12)))) | I11: =IF(G11="","",G11-H11) | J11: =IF(G11="","",G11+H11) | K11: =IF($A11="","",Master_Data!G11) | L11: =IF($A11="","",Master_Data!G12) | M11: =IF(AND(ISNUMBER(K11),ISNUMBER(L11)),L11-K11,"") | N11: =IF(G11="","",IF(AND(ISNUMBER(K11),ISNUMBER(L11)),IF(OR(F11="GOC",F11="OWC",F11="GWC",F11="OWC_TRANSITION",F11="GOC_TRANSITION"),IF(L11>=K11,"Supports","Conflicts"),"N/A"),"No Sw")) | O11: =IF(G11="","",Settings!$B$6*IF(OR(F11="GOC",F11="OWC",F11="GWC"),1,0.7)+Settings!$B$7*IF(N11="Supports",1,IF(N11="Conflicts",0,0.5))+Settings!$B$8*IF(AND(Master_Data!R11<>"",Master_Data!S11<>"",Master_Data!R12<>"",Master_Data!S12<>""),1,0.5)) | P11: =IF(G11="","",IF(N11="Conflicts","SW_CONFLICT",IF(OR(F11="GOC",F11="OWC",F11="GWC"),"DIRECT_FLUID_TRANSITION","TRANSITION_INTERVAL"))) | Q11: =IF(G11="","",IF(N11="Conflicts","Investigate contact interpretation / saturation behaviour",IF(OR(F11="OWC",F11="GOC",F11="GWC"),"Candidate contact — validate with logs, pressure and dynamic evidence","Transition zone — do not force to a sharp contact")))
A12: =IF(AND(Master_Data!A12<>"",Master_Data!A12=Master_Data!A13),Master_Data!A12,"") | B12: =IF($A12="","",Master_Data!B12) | C12: =IF($A12="","",Master_Data!B13) | D12: =IF($A12="","",Master_Data!Q12) | E12: =IF($A12="","",Master_Data!Q13) | F12: =IF($A12="","",IF(AND(D12="GAS",E12="OIL"),"GOC",IF(AND(D12="OIL",E12="WATER"),"OWC",IF(AND(D12="GAS",E12="WATER"),"GWC",IF(AND(D12="OIL",E12="OIL_WATER"),"OWC_TRANSITION",IF(AND(D12="OIL_WATER",E12="WATER"),"OWC_TRANSITION",IF(AND(D12="GAS",E12="GAS_WATER"),"GOC_TRANSITION",IF(AND(D12="GAS_WATER",E12="OIL"),"GOC_TRANSITION",IF(OR(D12="OIL_WATER",D12="GAS_WATER"),"TRANSITION_INTERVAL",""))))))))) | G12: =IF(OR(F12="",Master_Data!R12="",Master_Data!S12=""),"",IF(RIGHT(F12,10)="TRANSITION",AVERAGE(Master_Data!R12:Master_Data!S12),AVERAGE(Master_Data!S12,Master_Data!R13))) | H12: =IF(G12="","",MAX(Settings!$B$4,Settings!$B$5*AVERAGE(IF(Master_Data!O12<>"",Master_Data!O12,Master_Data!H12),IF(Master_Data!O13<>"",Master_Data!O13,Master_Data!H13)))) | I12: =IF(G12="","",G12-H12) | J12: =IF(G12="","",G12+H12) | K12: =IF($A12="","",Master_Data!G12) | L12: =IF($A12="","",Master_Data!G13) | M12: =IF(AND(ISNUMBER(K12),ISNUMBER(L12)),L12-K12,"") | N12: =IF(G12="","",IF(AND(ISNUMBER(K12),ISNUMBER(L12)),IF(OR(F12="GOC",F12="OWC",F12="GWC",F12="OWC_TRANSITION",F12="GOC_TRANSITION"),IF(L12>=K12,"Supports","Conflicts"),"N/A"),"No Sw")) | O12: =IF(G12="","",Settings!$B$6*IF(OR(F12="GOC",F12="OWC",F12="GWC"),1,0.7)+Settings!$B$7*IF(N12="Supports",1,IF(N12="Conflicts",0,0.5))+Settings!$B$8*IF(AND(Master_Data!R12<>"",Master_Data!S12<>"",Master_Data!R13<>"",Master_Data!S13<>""),1,0.5)) | P12: =IF(G12="","",IF(N12="Conflicts","SW_CONFLICT",IF(OR(F12="GOC",F12="OWC",F12="GWC"),"DIRECT_FLUID_TRANSITION","TRANSITION_INTERVAL"))) | Q12: =IF(G12="","",IF(N12="Conflicts","Investigate contact interpretation / saturation behaviour",IF(OR(F12="OWC",F12="GOC",F12="GWC"),"Candidate contact — validate with logs, pressure and dynamic evidence","Transition zone — do not force to a sharp contact")))
A13: =IF(AND(Master_Data!A13<>"",Master_Data!A13=Master_Data!A14),Master_Data!A13,"") | B13: =IF($A13="","",Master_Data!B13) | C13: =IF($A13="","",Master_Data!B14) | D13: =IF($A13="","",Master_Data!Q13) | E13: =IF($A13="","",Master_Data!Q14) | F13: =IF($A13="","",IF(AND(D13="GAS",E13="OIL"),"GOC",IF(AND(D13="OIL",E13="WATER"),"OWC",IF(AND(D13="GAS",E13="WATER"),"GWC",IF(AND(D13="OIL",E13="OIL_WATER"),"OWC_TRANSITION",IF(AND(D13="OIL_WATER",E13="WATER"),"OWC_TRANSITION",IF(AND(D13="GAS",E13="GAS_WATER"),"GOC_TRANSITION",IF(AND(D13="GAS_WATER",E13="OIL"),"GOC_TRANSITION",IF(OR(D13="OIL_WATER",D13="GAS_WATER"),"TRANSITION_INTERVAL",""))))))))) | G13: =IF(OR(F13="",Master_Data!R13="",Master_Data!S13=""),"",IF(RIGHT(F13,10)="TRANSITION",AVERAGE(Master_Data!R13:Master_Data!S13),AVERAGE(Master_Data!S13,Master_Data!R14))) | H13: =IF(G13="","",MAX(Settings!$B$4,Settings!$B$5*AVERAGE(IF(Master_Data!O13<>"",Master_Data!O13,Master_Data!H13),IF(Master_Data!O14<>"",Master_Data!O14,Master_Data!H14)))) | I13: =IF(G13="","",G13-H13) | J13: =IF(G13="","",G13+H13) | K13: =IF($A13="","",Master_Data!G13) | L13: =IF($A13="","",Master_Data!G14) | M13: =IF(AND(ISNUMBER(K13),ISNUMBER(L13)),L13-K13,"") | N13: =IF(G13="","",IF(AND(ISNUMBER(K13),ISNUMBER(L13)),IF(OR(F13="GOC",F13="OWC",F13="GWC",F13="OWC_TRANSITION",F13="GOC_TRANSITION"),IF(L13>=K13,"Supports","Conflicts"),"N/A"),"No Sw")) | O13: =IF(G13="","",Settings!$B$6*IF(OR(F13="GOC",F13="OWC",F13="GWC"),1,0.7)+Settings!$B$7*IF(N13="Supports",1,IF(N13="Conflicts",0,0.5))+Settings!$B$8*IF(AND(Master_Data!R13<>"",Master_Data!S13<>"",Master_Data!R14<>"",Master_Data!S14<>""),1,0.5)) | P13: =IF(G13="","",IF(N13="Conflicts","SW_CONFLICT",IF(OR(F13="GOC",F13="OWC",F13="GWC"),"DIRECT_FLUID_TRANSITION","TRANSITION_INTERVAL"))) | Q13: =IF(G13="","",IF(N13="Conflicts","Investigate contact interpretation / saturation behaviour",IF(OR(F13="OWC",F13="GOC",F13="GWC"),"Candidate contact — validate with logs, pressure and dynamic evidence","Transition zone — do not force to a sharp contact")))
... A1000: =IF(AND(Master_Data!A1000<>"",Master_Data!A1000=Master_Data!A1001),Master_Data!A1000,"") | B1000: =IF($A1000="","",Master_Data!B1000) | C1000: =IF($A1000="","",Master_Data!B1001) | D1000: =IF($A1000="","",Master_Data!Q1000) | E1000: =IF($A1000="","",Master_Data!Q1001) | F1000: =IF($A1000="","",IF(AND(D1000="GAS",E1000="OIL"),"GOC",IF(AND(D1000="OIL",E1000="WATER"),"OWC",IF(AND(D1000="GAS",E1000="WATER"),"GWC",IF(AND(D1000="OIL",E1000="OIL_WATER"),"OWC_TRANSITION",IF(AND(D1000="OIL_WATER",E1000="WATER"),"OWC_TRANSITION",IF(AND(D1000="GAS",E1000="GAS_WATER"),"GOC_TRANSITION",IF(AND(D1000="GAS_WATER",E1000="OIL"),"GOC_TRANSITION",IF(OR(D1000="OIL_WATER",D1000="GAS_WATER"),"TRANSITION_INTERVAL",""))))))))) | G1000: =IF(OR(F1000="",Master_Data!R1000="",Master_Data!S1000=""),"",IF(RIGHT(F1000,10)="TRANSITION",AVERAGE(Master_Data!R1000:Master_Data!S1000),AVERAGE(Master_Data!S1000,Master_Data!R1001))) | H1000: =IF(G1000="","",MAX(Settings!$B$4,Settings!$B$5*AVERAGE(IF(Master_Data!O1000<>"",Master_Data!O1000,Master_Data!H1000),IF(Master_Data!O1001<>"",Master_Data!O1001,Master_Data!H1001)))) | I1000: =IF(G1000="","",G1000-H1000) | J1000: =IF(G1000="","",G1000+H1000) | K1000: =IF($A1000="","",Master_Data!G1000) | L1000: =IF($A1000="","",Master_Data!G1001) | M1000: =IF(AND(ISNUMBER(K1000),ISNUMBER(L1000)),L1000-K1000,"") | N1000: =IF(G1000="","",IF(AND(ISNUMBER(K1000),ISNUMBER(L1000)),IF(OR(F1000="GOC",F1000="OWC",F1000="GWC",F1000="OWC_TRANSITION",F1000="GOC_TRANSITION"),IF(L1000>=K1000,"Supports","Conflicts"),"N/A"),"No Sw")) | O1000: =IF(G1000="","",Settings!$B$6*IF(OR(F1000="GOC",F1000="OWC",F1000="GWC"),1,0.7)+Settings!$B$7*IF(N1000="Supports",1,IF(N1000="Conflicts",0,0.5))+Settings!$B$8*IF(AND(Master_Data!R1000<>"",Master_Data!S1000<>"",Master_Data!R1001<>"",Master_Data!S1001<>""),1,0.5)) | P1000: =IF(G1000="","",IF(N1000="Conflicts","SW_CONFLICT",IF(OR(F1000="GOC",F1000="OWC",F1000="GWC"),"DIRECT_FLUID_TRANSITION","TRANSITION_INTERVAL"))) | Q1000: =IF(G1000="","",IF(N1000="Conflicts","Investigate contact interpretation / saturation behaviour",IF(OR(F1000="OWC",F1000="GOC",F1000="GWC"),"Candidate contact — validate with logs, pressure and dynamic evidence","Transition zone — do not force to a sharp contact")))

Sheet Contact_Summary
A1: Well | B1: GOC count | C1: GOC median TVD | D1: GOC P10 | E1: GOC P90 | F1: OWC count | G1: OWC median TVD | H1: OWC P10 | I1: OWC P90 | J1: GWC count | K1: GWC median TVD | L1: GWC P10 | M1: GWC P90
A2: X1 | B2: =IF($A2="","",COUNTIFS(Contact_Detector!$A$2:$A$1000,$A2,Contact_Detector!$F$2:$F$1000,"GOC")) | C2: =IFERROR(MEDIAN(FILTER(Contact_Detector!$G$2:$G$1000,(Contact_Detector!$A$2:$A$1000=$A2)*(Contact_Detector!$F$2:$F$1000="GOC"))),"") | D2: =IFERROR(PERCENTILE.INC(FILTER(Contact_Detector!$G$2:$G$1000,(Contact_Detector!$A$2:$A$1000=$A2)*(Contact_Detector!$F$2:$F$1000="GOC")),0.1),"") | E2: =IFERROR(PERCENTILE.INC(FILTER(Contact_Detector!$G$2:$G$1000,(Contact_Detector!$A$2:$A$1000=$A2)*(Contact_Detector!$F$2:$F$1000="GOC")),0.9),"") | F2: =IF($A2="","",COUNTIFS(Contact_Detector!$A$2:$A$1000,$A2,Contact_Detector!$F$2:$F$1000,"OWC")) | G2: =IFERROR(MEDIAN(FILTER(Contact_Detector!$G$2:$G$1000,(Contact_Detector!$A$2:$A$1000=$A2)*(Contact_Detector!$F$2:$F$1000="OWC"))),"") | H2: =IFERROR(PERCENTILE.INC(FILTER(Contact_Detector!$G$2:$G$1000,(Contact_Detector!$A$2:$A$1000=$A2)*(Contact_Detector!$F$2:$F$1000="OWC")),0.1),"") | I2: =IFERROR(PERCENTILE.INC(FILTER(Contact_Detector!$G$2:$G$1000,(Contact_Detector!$A$2:$A$1000=$A2)*(Contact_Detector!$F$2:$F$1000="OWC")),0.9),"") | J2: =IF($A2="","",COUNTIFS(Contact_Detector!$A$2:$A$1000,$A2,Contact_Detector!$F$2:$F$1000,"GWC")) | K2: =IFERROR(MEDIAN(FILTER(Contact_Detector!$G$2:$G$1000,(Contact_Detector!$A$2:$A$1000=$A2)*(Contact_Detector!$F$2:$F$1000="GWC"))),"") | L2: =IFERROR(PERCENTILE.INC(FILTER(Contact_Detector!$G$2:$G$1000,(Contact_Detector!$A$2:$A$1000=$A2)*(Contact_Detector!$F$2:$F$1000="GWC")),0.1),"") | M2: =IFERROR(PERCENTILE.INC(FILTER(Contact_Detector!$G$2:$G$1000,(Contact_Detector!$A$2:$A$1000=$A2)*(Contact_Detector!$F$2:$F$1000="GWC")),0.9),"")
A3: X2 | B3: =IF($A3="","",COUNTIFS(Contact_Detector!$A$2:$A$1000,$A3,Contact_Detector!$F$2:$F$1000,"GOC")) | C3: =IFERROR(MEDIAN(FILTER(Contact_Detector!$G$2:$G$1000,(Contact_Detector!$A$2:$A$1000=$A3)*(Contact_Detector!$F$2:$F$1000="GOC"))),"") | D3: =IFERROR(PERCENTILE.INC(FILTER(Contact_Detector!$G$2:$G$1000,(Contact_Detector!$A$2:$A$1000=$A3)*(Contact_Detector!$F$2:$F$1000="GOC")),0.1),"") | E3: =IFERROR(PERCENTILE.INC(FILTER(Contact_Detector!$G$2:$G$1000,(Contact_Detector!$A$2:$A$1000=$A3)*(Contact_Detector!$F$2:$F$1000="GOC")),0.9),"") | F3: =IF($A3="","",COUNTIFS(Contact_Detector!$A$2:$A$1000,$A3,Contact_Detector!$F$2:$F$1000,"OWC")) | G3: =IFERROR(MEDIAN(FILTER(Contact_Detector!$G$2:$G$1000,(Contact_Detector!$A$2:$A$1000=$A3)*(Contact_Detector!$F$2:$F$1000="OWC"))),"") | H3: =IFERROR(PERCENTILE.INC(FILTER(Contact_Detector!$G$2:$G$1000,(Contact_Detector!$A$2:$A$1000=$A3)*(Contact_Detector!$F$2:$F$1000="OWC")),0.1),"") | I3: =IFERROR(PERCENTILE.INC(FILTER(Contact_Detector!$G$2:$G$1000,(Contact_Detector!$A$2:$A$1000=$A3)*(Contact_Detector!$F$2:$F$1000="OWC")),0.9),"") | J3: =IF($A3="","",COUNTIFS(Contact_Detector!$A$2:$A$1000,$A3,Contact_Detector!$F$2:$F$1000,"GWC")) | K3: =IFERROR(MEDIAN(FILTER(Contact_Detector!$G$2:$G$1000,(Contact_Detector!$A$2:$A$1000=$A3)*(Contact_Detector!$F$2:$F$1000="GWC"))),"") | L3: =IFERROR(PERCENTILE.INC(FILTER(Contact_Detector!$G$2:$G$1000,(Contact_Detector!$A$2:$A$1000=$A3)*(Contact_Detector!$F$2:$F$1000="GWC")),0.1),"") | M3: =IFERROR(PERCENTILE.INC(FILTER(Contact_Detector!$G$2:$G$1000,(Contact_Detector!$A$2:$A$1000=$A3)*(Contact_Detector!$F$2:$F$1000="GWC")),0.9),"")
A4: X3 | B4: =IF($A4="","",COUNTIFS(Contact_Detector!$A$2:$A$1000,$A4,Contact_Detector!$F$2:$F$1000,"GOC")) | C4: =IFERROR(MEDIAN(FILTER(Contact_Detector!$G$2:$G$1000,(Contact_Detector!$A$2:$A$1000=$A4)*(Contact_Detector!$F$2:$F$1000="GOC"))),"") | D4: =IFERROR(PERCENTILE.INC(FILTER(Contact_Detector!$G$2:$G$1000,(Contact_Detector!$A$2:$A$1000=$A4)*(Contact_Detector!$F$2:$F$1000="GOC")),0.1),"") | E4: =IFERROR(PERCENTILE.INC(FILTER(Contact_Detector!$G$2:$G$1000,(Contact_Detector!$A$2:$A$1000=$A4)*(Contact_Detector!$F$2:$F$1000="GOC")),0.9),"") | F4: =IF($A4="","",COUNTIFS(Contact_Detector!$A$2:$A$1000,$A4,Contact_Detector!$F$2:$F$1000,"OWC")) | G4: =IFERROR(MEDIAN(FILTER(Contact_Detector!$G$2:$G$1000,(Contact_Detector!$A$2:$A$1000=$A4)*(Contact_Detector!$F$2:$F$1000="OWC"))),"") | H4: =IFERROR(PERCENTILE.INC(FILTER(Contact_Detector!$G$2:$G$1000,(Contact_Detector!$A$2:$A$1000=$A4)*(Contact_Detector!$F$2:$F$1000="OWC")),0.1),"") | I4: =IFERROR(PERCENTILE.INC(FILTER(Contact_Detector!$G$2:$G$1000,(Contact_Detector!$A$2:$A$1000=$A4)*(Contact_Detector!$F$2:$F$1000="OWC")),0.9),"") | J4: =IF($A4="","",COUNTIFS(Contact_Detector!$A$2:$A$1000,$A4,Contact_Detector!$F$2:$F$1000,"GWC")) | K4: =IFERROR(MEDIAN(FILTER(Contact_Detector!$G$2:$G$1000,(Contact_Detector!$A$2:$A$1000=$A4)*(Contact_Detector!$F$2:$F$1000="GWC"))),"") | L4: =IFERROR(PERCENTILE.INC(FILTER(Contact_Detector!$G$2:$G$1000,(Contact_Detector!$A$2:$A$1000=$A4)*(Contact_Detector!$F$2:$F$1000="GWC")),0.1),"") | M4: =IFERROR(PERCENTILE.INC(FILTER(Contact_Detector!$G$2:$G$1000,(Contact_Detector!$A$2:$A$1000=$A4)*(Contact_Detector!$F$2:$F$1000="GWC")),0.9),"")
A5: X4 | B5: =IF($A5="","",COUNTIFS(Contact_Detector!$A$2:$A$1000,$A5,Contact_Detector!$F$2:$F$1000,"GOC")) | C5: =IFERROR(MEDIAN(FILTER(Contact_Detector!$G$2:$G$1000,(Contact_Detector!$A$2:$A$1000=$A5)*(Contact_Detector!$F$2:$F$1000="GOC"))),"") | D5: =IFERROR(PERCENTILE.INC(FILTER(Contact_Detector!$G$2:$G$1000,(Contact_Detector!$A$2:$A$1000=$A5)*(Contact_Detector!$F$2:$F$1000="GOC")),0.1),"") | E5: =IFERROR(PERCENTILE.INC(FILTER(Contact_Detector!$G$2:$G$1000,(Contact_Detector!$A$2:$A$1000=$A5)*(Contact_Detector!$F$2:$F$1000="GOC")),0.9),"") | F5: =IF($A5="","",COUNTIFS(Contact_Detector!$A$2:$A$1000,$A5,Contact_Detector!$F$2:$F$1000,"OWC")) | G5: =IFERROR(MEDIAN(FILTER(Contact_Detector!$G$2:$G$1000,(Contact_Detector!$A$2:$A$1000=$A5)*(Contact_Detector!$F$2:$F$1000="OWC"))),"") | H5: =IFERROR(PERCENTILE.INC(FILTER(Contact_Detector!$G$2:$G$1000,(Contact_Detector!$A$2:$A$1000=$A5)*(Contact_Detector!$F$2:$F$1000="OWC")),0.1),"") | I5: =IFERROR(PERCENTILE.INC(FILTER(Contact_Detector!$G$2:$G$1000,(Contact_Detector!$A$2:$A$1000=$A5)*(Contact_Detector!$F$2:$F$1000="OWC")),0.9),"") | J5: =IF($A5="","",COUNTIFS(Contact_Detector!$A$2:$A$1000,$A5,Contact_Detector!$F$2:$F$1000,"GWC")) | K5: =IFERROR(MEDIAN(FILTER(Contact_Detector!$G$2:$G$1000,(Contact_Detector!$A$2:$A$1000=$A5)*(Contact_Detector!$F$2:$F$1000="GWC"))),"") | L5: =IFERROR(PERCENTILE.INC(FILTER(Contact_Detector!$G$2:$G$1000,(Contact_Detector!$A$2:$A$1000=$A5)*(Contact_Detector!$F$2:$F$1000="GWC")),0.1),"") | M5: =IFERROR(PERCENTILE.INC(FILTER(Contact_Detector!$G$2:$G$1000,(Contact_Detector!$A$2:$A$1000=$A5)*(Contact_Detector!$F$2:$F$1000="GWC")),0.9),"")
A6: X5 | B6: =IF($A6="","",COUNTIFS(Contact_Detector!$A$2:$A$1000,$A6,Contact_Detector!$F$2:$F$1000,"GOC")) | C6: =IFERROR(MEDIAN(FILTER(Contact_Detector!$G$2:$G$1000,(Contact_Detector!$A$2:$A$1000=$A6)*(Contact_Detector!$F$2:$F$1000="GOC"))),"") | D6: =IFERROR(PERCENTILE.INC(FILTER(Contact_Detector!$G$2:$G$1000,(Contact_Detector!$A$2:$A$1000=$A6)*(Contact_Detector!$F$2:$F$1000="GOC")),0.1),"") | E6: =IFERROR(PERCENTILE.INC(FILTER(Contact_Detector!$G$2:$G$1000,(Contact_Detector!$A$2:$A$1000=$A6)*(Contact_Detector!$F$2:$F$1000="GOC")),0.9),"") | F6: =IF($A6="","",COUNTIFS(Contact_Detector!$A$2:$A$1000,$A6,Contact_Detector!$F$2:$F$1000,"OWC")) | G6: =IFERROR(MEDIAN(FILTER(Contact_Detector!$G$2:$G$1000,(Contact_Detector!$A$2:$A$1000=$A6)*(Contact_Detector!$F$2:$F$1000="OWC"))),"") | H6: =IFERROR(PERCENTILE.INC(FILTER(Contact_Detector!$G$2:$G$1000,(Contact_Detector!$A$2:$A$1000=$A6)*(Contact_Detector!$F$2:$F$1000="OWC")),0.1),"") | I6: =IFERROR(PERCENTILE.INC(FILTER(Contact_Detector!$G$2:$G$1000,(Contact_Detector!$A$2:$A$1000=$A6)*(Contact_Detector!$F$2:$F$1000="OWC")),0.9),"") | J6: =IF($A6="","",COUNTIFS(Contact_Detector!$A$2:$A$1000,$A6,Contact_Detector!$F$2:$F$1000,"GWC")) | K6: =IFERROR(MEDIAN(FILTER(Contact_Detector!$G$2:$G$1000,(Contact_Detector!$A$2:$A$1000=$A6)*(Contact_Detector!$F$2:$F$1000="GWC"))),"") | L6: =IFERROR(PERCENTILE.INC(FILTER(Contact_Detector!$G$2:$G$1000,(Contact_Detector!$A$2:$A$1000=$A6)*(Contact_Detector!$F$2:$F$1000="GWC")),0.1),"") | M6: =IFERROR(PERCENTILE.INC(FILTER(Contact_Detector!$G$2:$G$1000,(Contact_Detector!$A$2:$A$1000=$A6)*(Contact_Detector!$F$2:$F$1000="GWC")),0.9),"")
